Workbook
Name UPDATE: 'Data Sheet'!$E$1

Sheet Profit & Loss
A1: ='Data Sheet'!B1 -> INFOSYS LTD | H1: =UPDATE | M1: SCREENER.IN
A3: Narration | B3: ='Data Sheet'!B16 -> 42460 | C3: ='Data Sheet'!C16 -> 42825 | D3: ='Data Sheet'!D16 -> 43190 | E3: ='Data Sheet'!E16 -> 43555 | F3: ='Data Sheet'!F16 -> 43921 | G3: ='Data Sheet'!G16 -> 44286 | H3: ='Data Sheet'!H16 -> 44651 | I3: ='Data Sheet'!I16 -> 45016 | ... K3: ='Data Sheet'!K16 -> 45747 | L3: Trailing | M3: Best Case | N3: Worst Case
A4: Sales | B4: ='Data Sheet'!B17 -> 62441 | C4: ='Data Sheet'!C17 -> 68484 | D4: ='Data Sheet'!D17 -> 70522 | E4: ='Data Sheet'!E17 -> 82675 | F4: ='Data Sheet'!F17 -> 90791 | G4: ='Data Sheet'!G17 -> 100472 | H4: ='Data Sheet'!H17 -> 121641 | I4: ='Data Sheet'!I17 -> 146767 | ... K4: ='Data Sheet'!K17 -> 162990 | L4: =SUM(Quarters!H4:K4) -> 173173 | M4: =$K4+M23*K4 -> 179688.91 | N4: =$K4+N23*L4 -> 173809.2
A5: Expenses | B5: =SUM('Data Sheet'!B18,'Data Sheet'!B20:B24, -1*'Data Sheet'!B19) -> 45362 | C5: =SUM('Data Sheet'!C18,'Data Sheet'!C20:C24, -1*'Data Sheet'!C19) -> 49880 | D5: =SUM('Data Sheet'!D18,'Data Sheet'!D20:D24, -1*'Data Sheet'!D19) -> 51700 | E5: =SUM('Data Sheet'!E18,'Data Sheet'!E20:E24, -1*'Data Sheet'!E19) -> 62505 | F5: =SUM('Data Sheet'!F18,'Data Sheet'!F20:F24, -1*'Data Sheet'!F19) -> 68524 | G5: =SUM('Data Sheet'!G18,'Data Sheet'!G20:G24, -1*'Data Sheet'!G19) -> 72583 | H5: =SUM('Data Sheet'!H18,'Data Sheet'!H20:H24, -1*'Data Sheet'!H19) -> 90150 | I5: =SUM('Data Sheet'!I18,'Data Sheet'!I20:I24, -1*'Data Sheet'!I19) -> 111637 | ... K5: =SUM('Data Sheet'!K18,'Data Sheet'!K20:K24, -1*'Data Sheet'!K19) -> 123754 | L5: =SUM(Quarters!H5:K5) -> 132187 | M5: =M4-M6 -> 136730.88 | N5: =N4-N6 -> 132672.62
A6: Operating Profit | B6: =B4-B5 -> 17079 | C6: =C4-C5 -> 18604 | D6: =D4-D5 -> 18822 | E6: =E4-E5 -> 20170 | F6: =F4-F5 -> 22267 | G6: =G4-G5 -> 27889 | H6: =H4-H5 -> 31491 | I6: =I4-I5 -> 35130 | ... K6: =K4-K5 -> 39236 | L6: =SUM(Quarters!H6:K6) -> 40986 | M6: =M4*M24 -> 42958.038 | N6: =N4*N24 -> 41136.573
A7: Other Income | B7: ='Data Sheet'!B25 -> 3120 | C7: ='Data Sheet'!C25 -> 3050 | D7: ='Data Sheet'!D25 -> 3311 | E7: ='Data Sheet'!E25 -> 2882 | F7: ='Data Sheet'!F25 -> 2803 | G7: ='Data Sheet'!G25 -> 2201 | H7: ='Data Sheet'!H25 -> 2295 | I7: ='Data Sheet'!I25 -> 2701 | ... K7: ='Data Sheet'!K25 -> 3600 | L7: =SUM(Quarters!H7:K7) -> 3064 | M7: 0 | N7: 0
A8: Depreciation | B8: ='Data Sheet'!B26 -> 1459 | C8: ='Data Sheet'!C26 -> 1703 | D8: ='Data Sheet'!D26 -> 1863 | E8: ='Data Sheet'!E26 -> 2011 | F8: ='Data Sheet'!F26 -> 2893 | G8: ='Data Sheet'!G26 -> 3267 | H8: ='Data Sheet'!H26 -> 3476 | I8: ='Data Sheet'!I26 -> 4225 | ... K8: ='Data Sheet'!K26 -> 4812 | L8: =SUM(Quarters!H8:K8) -> 4776 | M8: =+$L8 -> 4776 | N8: =+$L8 -> 4776
A9: Interest | B9: ='Data Sheet'!B27 -> 0 | C9: ='Data Sheet'!C27 -> 0 | D9: ='Data Sheet'!D27 -> 0 | E9: ='Data Sheet'!E27 -> 0 | F9: ='Data Sheet'!F27 -> 170 | G9: ='Data Sheet'!G27 -> 195 | H9: ='Data Sheet'!H27 -> 200 | I9: ='Data Sheet'!I27 -> 284 | ... K9: ='Data Sheet'!K27 -> 416 | L9: =SUM(Quarters!H9:K9) -> 413 | M9: =+$L9 -> 413 | N9: =+$L9 -> 413
A10: Profit before tax | B10: ='Data Sheet'!B28 -> 18740 | C10: ='Data Sheet'!C28 -> 19951 | D10: ='Data Sheet'!D28 -> 20270 | E10: ='Data Sheet'!E28 -> 21041 | F10: ='Data Sheet'!F28 -> 22007 | G10: ='Data Sheet'!G28 -> 26628 | H10: ='Data Sheet'!H28 -> 30110 | I10: ='Data Sheet'!I28 -> 33322 | ... K10: ='Data Sheet'!K28 -> 37608 | L10: =SUM(Quarters!H10:K10) -> 38861 | M10: =M6+M7-SUM(M8:M9) -> 37769.038 | N10: =N6+N7-SUM(N8:N9) -> 35947.573
A11: Tax | B11: ='Data Sheet'!B29 -> 5251 | C11: ='Data Sheet'!C29 -> 5598 | D11: ='Data Sheet'!D29 -> 4241 | E11: ='Data Sheet'!E29 -> 5631 | F11: ='Data Sheet'!F29 -> 5368 | G11: ='Data Sheet'!G29 -> 7205 | H11: ='Data Sheet'!H29 -> 7964 | I11: ='Data Sheet'!I29 -> 9214 | ... K11: ='Data Sheet'!K29 -> 10858 | L11: =SUM(Quarters!H11:K11) -> 10858 | M11: =IF($L10>0,$L11/$L10,0) -> 0.27940609 | N11: =IF($L10>0,$L11/$L10,0) -> 0.27940609
A12: Net profit | B12: ='Data Sheet'!B30 -> 13489 | C12: ='Data Sheet'!C30 -> 14353 | D12: ='Data Sheet'!D30 -> 16029 | E12: ='Data Sheet'!E30 -> 15404 | F12: ='Data Sheet'!F30 -> 16594 | G12: ='Data Sheet'!G30 -> 19351 | H12: ='Data Sheet'!H30 -> 22110 | I12: ='Data Sheet'!I30 -> 24095 | ... K12: ='Data Sheet'!K30 -> 26713 | L12: =SUM(Quarters!H12:K12) -> 27972 | M12: =M10-M11*M10 -> 27216.139 | N12: =N10-N11*N10 -> 25903.602
A13: EPS | B13: =IF('Data Sheet'!B93>0,B12/'Data Sheet'!B93,0) -> 29.362851 | C13: =IF('Data Sheet'!C93>0,C12/'Data Sheet'!C93,0) -> 31.243606 | D13: =IF('Data Sheet'!D93>0,D12/'Data Sheet'!D93,0) -> 36.694748 | E13: =IF('Data Sheet'!E93>0,E12/'Data Sheet'!E93,0) -> 35.258303 | F13: =IF('Data Sheet'!F93>0,F12/'Data Sheet'!F93,0) -> 38.962198 | G13: =IF('Data Sheet'!G93>0,G12/'Data Sheet'!G93,0) -> 45.41742 | H13: =IF('Data Sheet'!H93>0,H12/'Data Sheet'!H93,0) -> 52.559013 | I13: =IF('Data Sheet'!I93>0,I12/'Data Sheet'!I93,0) -> 58.079834 | ... K13: =IF('Data Sheet'!K93>0,K12/'Data Sheet'!K93,0) -> 64.317531 | L13: =IF('Data Sheet'!$B6>0,'Profit & Loss'!L12/'Data Sheet'!$B6,0) -> 68.974851 | M13: =IF('Data Sheet'!$B6>0,'Profit & Loss'!M12/'Data Sheet'!$B6,0) -> 67.111008 | N13: =IF('Data Sheet'!$B6>0,'Profit & Loss'!N12/'Data Sheet'!$B6,0) -> 63.874485
A14: Price to earning | B14: =IF(B15>0,B15/B13,"") -> 20.745601 | C14: =IF(C15>0,C15/C13,"") -> 16.359507 | D14: =IF(D15>0,D15/D13,"") -> 15.421825 | E14: =IF(E15>0,E15/E13,"") -> 21.097158 | F14: =IF(F15>0,F15/F13,"") -> 16.464677 | G14: =IF(G15>0,G15/G13,"") -> 30.121702 | H14: =IF(H15>0,H15/H13,"") -> 36.280171 | I14: =IF(I15>0,I15/I13,"") -> 24.585986 | ... K14: =IF(K15>0,K15/K13,"") -> 24.420247 | L14: =IF(L13>0,L15/L13,0) -> 18.848899 | M14: =M25 -> 22.889769 | N14: =N25 -> 18.848899
A15: Price | B15: ='Data Sheet'!B90 -> 609.15 | C15: ='Data Sheet'!C90 -> 511.13 | D15: ='Data Sheet'!D90 -> 565.9 | E15: ='Data Sheet'!E90 -> 743.85 | F15: ='Data Sheet'!F90 -> 641.5 | G15: ='Data Sheet'!G90 -> 1368.05 | H15: ='Data Sheet'!H90 -> 1906.85 | I15: ='Data Sheet'!I90 -> 1427.95 | ... K15: ='Data Sheet'!K90 -> 1570.65 | L15: ='Data Sheet'!B8 -> 1300.1 | M15: =M13*M14 -> 1536.1555 | N15: =N13*N14 -> 1203.9637
A17: RATIOS:
A18: Dividend Payout | B18: =IF('Data Sheet'!B30>0, 'Data Sheet'!B31/'Data Sheet'!B30, 0) -> 0.41132775 | C18: =IF('Data Sheet'!C30>0, 'Data Sheet'!C31/'Data Sheet'!C30, 0) -> 0.41047865 | D18: =IF('Data Sheet'!D30>0, 'Data Sheet'!D31/'Data Sheet'!D30, 0) -> 0.59052966 | E18: =IF('Data Sheet'!E30>0, 'Data Sheet'!E31/'Data Sheet'!E30, 0) -> 0.59870813 | F18: =IF('Data Sheet'!F30>0, 'Data Sheet'!F31/'Data Sheet'!F30, 0) -> 0.44757141 | G18: =IF('Data Sheet'!G30>0, 'Data Sheet'!G31/'Data Sheet'!G30, 0) -> 0.59271355 | H18: =IF('Data Sheet'!H30>0, 'Data Sheet'!H31/'Data Sheet'!H30, 0) -> 0.58831298 | I18: =IF('Data Sheet'!I30>0, 'Data Sheet'!I31/'Data Sheet'!I30, 0) -> 0.58390537 | ... K18: =IF('Data Sheet'!K30>0, 'Data Sheet'!K31/'Data Sheet'!K30, 0) -> 0.66738292
A19: OPM | B19: =IF(B6>0,B6/B4,0) -> 0.2735222 | C19: =IF(C6>0,C6/C4,0) -> 0.27165469 | D19: =IF(D6>0,D6/D4,0) -> 0.26689544 | E19: =IF(E6>0,E6/E4,0) -> 0.24396734 | F19: =IF(F6>0,F6/F4,0) -> 0.24525559 | G19: =IF(G6>0,G6/G4,0) -> 0.27757982 | H19: =IF(H6>0,H6/H4,0) -> 0.25888475 | I19: =IF(I6>0,I6/I4,0) -> 0.23935898 | ... L19: =IF(L6>0,L6/L4,0) -> 0.23667662
G22: TRENDS: | H22: 10 YEARS | I22: 7 YEARS | J22: 5 YEARS | K22: 3 YEARS | L22: RECENT | M22: BEST | N22: WORST
G23: Sales Growth | H23: =IF(B4=0,"",POWER($K4/B4,1/9)-1) -> 0.11249742 | I23: =IF(D4=0,"",POWER($K4/D4,1/7)-1) -> 0.12713678 | J23: =IF(F4=0,"",POWER($K4/F4,1/5)-1) -> 0.12414836 | K23: =IF(H4=0,"",POWER($K4/H4, 1/3)-1) -> 0.10245362 | L23: =IF(ISERROR(MAX(IF(J4=0,"",(K4-J4)/J4),IF(K4=0,"",(L4-K4)/K4))),"",MAX(IF(J4=0,"",(K4-J4)/J4),IF(K4=0,"",(L4-K4)/K4))) -> 0.062476226 | M23: =MAX(K23:L23) -> 0.10245362 | N23: =MIN(H23:L23) -> 0.062476226
G24: OPM | H24: =IF(SUM(B4:$K$4)=0,"",SUMPRODUCT(B19:$K$19,B4:$K$4)/SUM(B4:$K$4)) -> 0.25188575 | I24: =IF(SUM(E4:$K$4)=0,"",SUMPRODUCT(E19:$K$19,E4:$K$4)/SUM(E4:$K$4)) -> 0.24750467 | J24: =IF(SUM(G4:$K$4)=0,"",SUMPRODUCT(G19:$K$19,G4:$K$4)/SUM(G4:$K$4)) -> 0.24822913 | K24: =IF(SUM(I4:$K$4)=0, "", SUMPRODUCT(I19:$K$19,I4:$K$4)/SUM(I4:$K$4)) -> 0.23906894 | L24: =L19 -> 0.23667662 | M24: =MAX(K24:L24) -> 0.23906894 | N24: =MIN(H24:L24) -> 0.23667662
G25: Price to Earning | H25: =IF(ISERROR(AVERAGEIF(B14:$L14,">0")),"",AVERAGEIF(B14:$L14,">0")) -> 22.549975 | I25: =IF(ISERROR(AVERAGEIF(E14:$L14,">0")),"",AVERAGEIF(E14:$L14,">0")) -> 24.440348 | J25: =IF(ISERROR(AVERAGEIF(G14:$L14,">0")),"",AVERAGEIF(G14:$L14,">0")) -> 26.326825 | K25: =IF(ISERROR(AVERAGEIF(I14:$L14,">0")),"",AVERAGEIF(I14:$L14,">0")) -> 22.889769 | L25: =L14 -> 18.848899 | M25: =MAX(K25:L25) -> 22.889769 | N25: =MIN(H25:L25) -> 18.848899

Sheet Quarters
A1: ='Profit & Loss'!A1 -> INFOSYS LTD | E1: =UPDATE | J1: SCREENER.IN
A3: Narration | B3: ='Data Sheet'!B41 -> 45199 | C3: ='Data Sheet'!C41 -> 45291 | D3: ='Data Sheet'!D41 -> 45382 | E3: ='Data Sheet'!E41 -> 45473 | F3: ='Data Sheet'!F41 -> 45565 | G3: ='Data Sheet'!G41 -> 45657 | H3: ='Data Sheet'!H41 -> 45747 | I3: ='Data Sheet'!I41 -> 45838 | ... K3: ='Data Sheet'!K41 -> 46022
A4: Sales | B4: ='Data Sheet'!B42 -> 38994 | C4: ='Data Sheet'!C42 -> 38821 | D4: ='Data Sheet'!D42 -> 37923 | E4: ='Data Sheet'!E42 -> 39315 | F4: ='Data Sheet'!F42 -> 40986 | G4: ='Data Sheet'!G42 -> 41764 | H4: ='Data Sheet'!H42 -> 40925 | I4: ='Data Sheet'!I42 -> 42279 | ... K4: ='Data Sheet'!K42 -> 45479
A5: Expenses | B5: ='Data Sheet'!B43 -> 29554 | C5: ='Data Sheet'!C43 -> 29684 | D5: ='Data Sheet'!D43 -> 29139 | E5: ='Data Sheet'!E43 -> 29878 | F5: ='Data Sheet'!F43 -> 31177 | G5: ='Data Sheet'!G43 -> 31649 | H5: ='Data Sheet'!H43 -> 31051 | I5: ='Data Sheet'!I43 -> 32336 | ... K5: ='Data Sheet'!K43 -> 34845
A6: Operating Profit | B6: ='Data Sheet'!B50 -> 9440 | C6: ='Data Sheet'!C50 -> 9137 | D6: ='Data Sheet'!D50 -> 8784 | E6: ='Data Sheet'!E50 -> 9437 | F6: ='Data Sheet'!F50 -> 9809 | G6: ='Data Sheet'!G50 -> 10115 | H6: ='Data Sheet'!H50 -> 9874 | I6: ='Data Sheet'!I50 -> 9943 | ... K6: ='Data Sheet'!K50 -> 10634
A7: Other Income | B7: ='Data Sheet'!B44 -> 632 | C7: ='Data Sheet'!C44 -> 789 | D7: ='Data Sheet'!D44 -> 2729 | E7: ='Data Sheet'!E44 -> 838 | F7: ='Data Sheet'!F44 -> 712 | G7: ='Data Sheet'!G44 -> 859 | H7: ='Data Sheet'!H44 -> 1190 | I7: ='Data Sheet'!I44 -> 1042 | ... K7: ='Data Sheet'!K44 -> -150
A8: Depreciation | B8: ='Data Sheet'!B45 -> 1166 | C8: ='Data Sheet'!C45 -> 1176 | D8: ='Data Sheet'!D45 -> 1163 | E8: ='Data Sheet'!E45 -> 1149 | F8: ='Data Sheet'!F45 -> 1160 | G8: ='Data Sheet'!G45 -> 1203 | H8: ='Data Sheet'!H45 -> 1299 | I8: ='Data Sheet'!I45 -> 1140 | ... K8: ='Data Sheet'!K45 -> 1155
A9: Interest | B9: ='Data Sheet'!B46 -> 138 | C9: ='Data Sheet'!C46 -> 131 | D9: ='Data Sheet'!D46 -> 110 | E9: ='Data Sheet'!E46 -> 105 | F9: ='Data Sheet'!F46 -> 108 | G9: ='Data Sheet'!G46 -> 101 | H9: ='Data Sheet'!H46 -> 102 | I9: ='Data Sheet'!I46 -> 105 | ... K9: ='Data Sheet'!K46 -> 100
A10: Profit before tax | B10: ='Data Sheet'!B47 -> 8768 | C10: ='Data Sheet'!C47 -> 8619 | D10: ='Data Sheet'!D47 -> 10240 | E10: ='Data Sheet'!E47 -> 9021 | F10: ='Data Sheet'!F47 -> 9253 | G10: ='Data Sheet'!G47 -> 9670 | H10: ='Data Sheet'!H47 -> 9663 | I10: ='Data Sheet'!I47 -> 9740 | ... K10: ='Data Sheet'!K47 -> 9229
A11: Tax | B11: ='Data Sheet'!B48 -> 2553 | C11: ='Data Sheet'!C48 -> 2506 | D11: ='Data Sheet'!D48 -> 2265 | E11: ='Data Sheet'!E48 -> 2647 | F11: ='Data Sheet'!F48 -> 2737 | G11: ='Data Sheet'!G48 -> 2848 | H11: ='Data Sheet'!H48 -> 2625 | I11: ='Data Sheet'!I48 -> 2816 | ... K11: ='Data Sheet'!K48 -> 2563
A12: Net profit | B12: ='Data Sheet'!B49 -> 6212 | C12: ='Data Sheet'!C49 -> 6106 | D12: ='Data Sheet'!D49 -> 7969 | E12: ='Data Sheet'!E49 -> 6368 | F12: ='Data Sheet'!F49 -> 6506 | G12: ='Data Sheet'!G49 -> 6806 | H12: ='Data Sheet'!H49 -> 7033 | I12: ='Data Sheet'!I49 -> 6921 | ... K12: ='Data Sheet'!K49 -> 6654
A14: OPM | B14: =IF(B4>0,B6/B4,"") -> 0.24208853 | C14: =IF(C4>0,C6/C4,"") -> 0.2353623 | D14: =IF(D4>0,D6/D4,"") -> 0.23162724 | E14: =IF(E4>0,E6/E4,"") -> 0.24003561 | F14: =IF(F4>0,F6/F4,"") -> 0.23932562 | G14: =IF(G4>0,G6/G4,"") -> 0.24219423 | H14: =IF(H4>0,H6/H4,"") -> 0.24127062 | I14: =IF(I4>0,I6/I4,"") -> 0.23517586 | ... K14: =IF(K4>0,K6/K4,"") -> 0.2338222

Sheet Balance Sheet
A1: ='Profit & Loss'!A1 -> INFOSYS LTD | E1: =UPDATE | J1: SCREENER.IN
A3: Narration | B3: ='Data Sheet'!B56 -> 42460 | C3: ='Data Sheet'!C56 -> 42825 | D3: ='Data Sheet'!D56 -> 43190 | E3: ='Data Sheet'!E56 -> 43555 | F3: ='Data Sheet'!F56 -> 43921 | G3: ='Data Sheet'!G56 -> 44286 | H3: ='Data Sheet'!H56 -> 44651 | I3: ='Data Sheet'!I56 -> 45016 | ... K3: ='Data Sheet'!K56 -> 45747
A4: Equity Share Capital | B4: ='Data Sheet'!B57 -> 1144 | C4: ='Data Sheet'!C57 -> 1144 | D4: ='Data Sheet'!D57 -> 1088 | E4: ='Data Sheet'!E57 -> 2170 | F4: ='Data Sheet'!F57 -> 2122 | G4: ='Data Sheet'!G57 -> 2124 | H4: ='Data Sheet'!H57 -> 2098 | I4: ='Data Sheet'!I57 -> 2069 | ... K4: ='Data Sheet'!K57 -> 2073
A5: Reserves | B5: ='Data Sheet'!B58 -> 60600 | C5: ='Data Sheet'!C58 -> 67838 | D5: ='Data Sheet'!D58 -> 63835 | E5: ='Data Sheet'!E58 -> 62778 | F5: ='Data Sheet'!F58 -> 63328 | G5: ='Data Sheet'!G58 -> 74227 | H5: ='Data Sheet'!H58 -> 73252 | I5: ='Data Sheet'!I58 -> 73338 | ... K5: ='Data Sheet'!K58 -> 93745
A6: Borrowings | B6: ='Data Sheet'!B59 -> 0 | C6: ='Data Sheet'!C59 -> 0 | D6: ='Data Sheet'!D59 -> 0 | E6: ='Data Sheet'!E59 -> 0 | F6: ='Data Sheet'!F59 -> 4633 | G6: ='Data Sheet'!G59 -> 5325 | H6: ='Data Sheet'!H59 -> 5474 | I6: ='Data Sheet'!I59 -> 8299 | ... K6: ='Data Sheet'!K59 -> 8227
A7: Other Liabilities | B7: ='Data Sheet'!B60 -> 13354 | C7: ='Data Sheet'!C60 -> 14166 | D7: ='Data Sheet'!D60 -> 14426 | E7: ='Data Sheet'!E60 -> 19118 | F7: ='Data Sheet'!F60 -> 21717 | G7: ='Data Sheet'!G60 -> 25835 | H7: ='Data Sheet'!H60 -> 35905 | I7: ='Data Sheet'!I60 -> 40890 | ... K7: ='Data Sheet'!K60 -> 43750
A8: Total | B8: ='Data Sheet'!B61 -> 75098 | C8: ='Data Sheet'!C61 -> 83148 | D8: ='Data Sheet'!D61 -> 79349 | E8: ='Data Sheet'!E61 -> 84066 | F8: ='Data Sheet'!F61 -> 91800 | G8: ='Data Sheet'!G61 -> 107511 | H8: ='Data Sheet'!H61 -> 116729 | I8: ='Data Sheet'!I61 -> 124596 | ... K8: ='Data Sheet'!K61 -> 147795
A10: Net Block | B10: ='Data Sheet'!B62 -> 13386 | C10: ='Data Sheet'!C62 -> 14179 | D10: ='Data Sheet'!D62 -> 12574 | E10: ='Data Sheet'!E62 -> 15710 | F10: ='Data Sheet'!F62 -> 23789 | G10: ='Data Sheet'!G62 -> 25505 | H10: ='Data Sheet'!H62 -> 25800 | I10: ='Data Sheet'!I62 -> 29225 | ... K10: ='Data Sheet'!K62 -> 30961
A11: Capital Work in Progress | B11: ='Data Sheet'!B63 -> 960 | C11: ='Data Sheet'!C63 -> 1365 | D11: ='Data Sheet'!D63 -> 1606 | E11: ='Data Sheet'!E63 -> 1388 | F11: ='Data Sheet'!F63 -> 954 | G11: ='Data Sheet'!G63 -> 922 | H11: ='Data Sheet'!H63 -> 416 | I11: ='Data Sheet'!I63 -> 288 | ... K11: ='Data Sheet'!K63 -> 814
A12: Investments | B12: ='Data Sheet'!B64 -> 1892 | C12: ='Data Sheet'!C64 -> 16423 | D12: ='Data Sheet'!D64 -> 12163 | E12: ='Data Sheet'!E64 -> 11261 | F12: ='Data Sheet'!F64 -> 8792 | G12: ='Data Sheet'!G64 -> 14205 | H12: ='Data Sheet'!H64 -> 20324 | I12: ='Data Sheet'!I64 -> 19478 | ... K12: ='Data Sheet'!K64 -> 23541
A13: Other Assets | B13: ='Data Sheet'!B65 -> 58860 | C13: ='Data Sheet'!C65 -> 51181 | D13: ='Data Sheet'!D65 -> 53006 | E13: ='Data Sheet'!E65 -> 55707 | F13: ='Data Sheet'!F65 -> 58265 | G13: ='Data Sheet'!G65 -> 66879 | H13: ='Data Sheet'!H65 -> 70189 | I13: ='Data Sheet'!I65 -> 75605 | ... K13: ='Data Sheet'!K65 -> 92479
A14: Total | B14: ='Data Sheet'!B66 -> 75098 | C14: ='Data Sheet'!C66 -> 83148 | D14: ='Data Sheet'!D66 -> 79349 | E14: ='Data Sheet'!E66 -> 84066 | F14: ='Data Sheet'!F66 -> 91800 | G14: ='Data Sheet'!G66 -> 107511 | H14: ='Data Sheet'!H66 -> 116729 | I14: ='Data Sheet'!I66 -> 124596 | ... K14: ='Data Sheet'!K66 -> 147795
A16: Working Capital | B16: =B13-B7 -> 45506 | C16: =C13-C7 -> 37015 | D16: =D13-D7 -> 38580 | E16: =E13-E7 -> 36589 | F16: =F13-F7 -> 36548 | G16: =G13-G7 -> 41044 | H16: =H13-H7 -> 34284 | I16: =I13-I7 -> 34715 | ... K16: =K13-K7 -> 48729
A17: Debtors | B17: ='Data Sheet'!B67 -> 11330 | C17: ='Data Sheet'!C67 -> 12322 | D17: ='Data Sheet'!D67 -> 13142 | E17: ='Data Sheet'!E67 -> 14827 | F17: ='Data Sheet'!F67 -> 18487 | G17: ='Data Sheet'!G67 -> 19294 | H17: ='Data Sheet'!H67 -> 22698 | I17: ='Data Sheet'!I67 -> 25424 | ... K17: ='Data Sheet'!K67 -> 31158
A18: Inventory | B18: ='Data Sheet'!B68 -> 0 | C18: ='Data Sheet'!C68 -> 0 | D18: ='Data Sheet'!D68 -> 0 | E18: ='Data Sheet'!E68 -> 0 | F18: ='Data Sheet'!F68 -> 0 | G18: ='Data Sheet'!G68 -> 0 | H18: ='Data Sheet'!H68 -> 0 | I18: ='Data Sheet'!I68 -> 0 | ... K18: ='Data Sheet'!K68 -> 0
A20: Debtor Days | B20: =IF('Profit & Loss'!B4>0,'Balance Sheet'!B17/('Profit & Loss'!B4/365),0) -> 66.229721 | C20: =IF('Profit & Loss'!C4>0,'Balance Sheet'!C17/('Profit & Loss'!C4/365),0) -> 65.672712 | D20: =IF('Profit & Loss'!D4>0,'Balance Sheet'!D17/('Profit & Loss'!D4/365),0) -> 68.018916 | E20: =IF('Profit & Loss'!E4>0,'Balance Sheet'!E17/('Profit & Loss'!E4/365),0) -> 65.459389 | F20: =IF('Profit & Loss'!F4>0,'Balance Sheet'!F17/('Profit & Loss'!F4/365),0) -> 74.321849 | G20: =IF('Profit & Loss'!G4>0,'Balance Sheet'!G17/('Profit & Loss'!G4/365),0) -> 70.092265 | H20: =IF('Profit & Loss'!H4>0,'Balance Sheet'!H17/('Profit & Loss'!H4/365),0) -> 68.108368 | I20: =IF('Profit & Loss'!I4>0,'Balance Sheet'!I17/('Profit & Loss'!I4/365),0) -> 63.227837 | ... K20: =IF('Profit & Loss'!K4>0,'Balance Sheet'!K17/('Profit & Loss'!K4/365),0) -> 69.775262
A21: Inventory Turnover | B21: =IF('Balance Sheet'!B18>0,'Profit & Loss'!B4/'Balance Sheet'!B18,0) -> 0 | C21: =IF('Balance Sheet'!C18>0,'Profit & Loss'!C4/'Balance Sheet'!C18,0) -> 0 | D21: =IF('Balance Sheet'!D18>0,'Profit & Loss'!D4/'Balance Sheet'!D18,0) -> 0 | E21: =IF('Balance Sheet'!E18>0,'Profit & Loss'!E4/'Balance Sheet'!E18,0) -> 0 | F21: =IF('Balance Sheet'!F18>0,'Profit & Loss'!F4/'Balance Sheet'!F18,0) -> 0 | G21: =IF('Balance Sheet'!G18>0,'Profit & Loss'!G4/'Balance Sheet'!G18,0) -> 0 | H21: =IF('Balance Sheet'!H18>0,'Profit & Loss'!H4/'Balance Sheet'!H18,0) -> 0 | I21: =IF('Balance Sheet'!I18>0,'Profit & Loss'!I4/'Balance Sheet'!I18,0) -> 0 | ... K21: =IF('Balance Sheet'!K18>0,'Profit & Loss'!K4/'Balance Sheet'!K18,0) -> 0
A23: Return on Equity | B23: =IF(SUM('Balance Sheet'!B4:B5)>0,'Profit & Loss'!B12/SUM('Balance Sheet'!B4:B5),"") -> 0.21846657 | C23: =IF(SUM('Balance Sheet'!C4:C5)>0,'Profit & Loss'!C12/SUM('Balance Sheet'!C4:C5),"") -> 0.20806877 | D23: =IF(SUM('Balance Sheet'!D4:D5)>0,'Profit & Loss'!D12/SUM('Balance Sheet'!D4:D5),"") -> 0.24689247 | E23: =IF(SUM('Balance Sheet'!E4:E5)>0,'Profit & Loss'!E12/SUM('Balance Sheet'!E4:E5),"") -> 0.23717435 | F23: =IF(SUM('Balance Sheet'!F4:F5)>0,'Profit & Loss'!F12/SUM('Balance Sheet'!F4:F5),"") -> 0.25353705 | G23: =IF(SUM('Balance Sheet'!G4:G5)>0,'Profit & Loss'!G12/SUM('Balance Sheet'!G4:G5),"") -> 0.25344789 | H23: =IF(SUM('Balance Sheet'!H4:H5)>0,'Profit & Loss'!H12/SUM('Balance Sheet'!H4:H5),"") -> 0.29343066 | I23: =IF(SUM('Balance Sheet'!I4:I5)>0,'Profit & Loss'!I12/SUM('Balance Sheet'!I4:I5),"") -> 0.31953267 | ... K23: =IF(SUM('Balance Sheet'!K4:K5)>0,'Profit & Loss'!K12/SUM('Balance Sheet'!K4:K5),"") -> 0.27878895
A24: Return on Capital Emp | C24: =IF((B4+B5+B6+C4+C5+C6)>0,('Profit & Loss'!C10+'Profit & Loss'!C9)*2/(B4+B5+B6+C4+C5+C6),"") -> 0.30523385 | D24: =IF((C4+C5+C6+D4+D5+D6)>0,('Profit & Loss'!D10+'Profit & Loss'!D9)*2/(C4+C5+C6+D4+D5+D6),"") -> 0.30275195 | E24: =IF((D4+D5+D6+E4+E5+E6)>0,('Profit & Loss'!E10+'Profit & Loss'!E9)*2/(D4+D5+D6+E4+E5+E6),"") -> 0.32402923 | F24: =IF((E4+E5+E6+F4+F5+F6)>0,('Profit & Loss'!F10+'Profit & Loss'!F9)*2/(E4+E5+E6+F4+F5+F6),"") -> 0.32847272 | G24: =IF((F4+F5+F6+G4+G5+G6)>0,('Profit & Loss'!G10+'Profit & Loss'!G9)*2/(F4+F5+F6+G4+G5+G6),"") -> 0.35349469 | H24: =IF((G4+G5+G6+H4+H5+H6)>0,('Profit & Loss'!H10+'Profit & Loss'!H9)*2/(G4+G5+G6+H4+H5+H6),"") -> 0.37304615 | I24: =IF((H4+H5+H6+I4+I5+I6)>0,('Profit & Loss'!I10+'Profit & Loss'!I9)*2/(H4+H5+H6+I4+I5+I6),"") -> 0.40850909 | J24: =IF((I4+I5+I6+J4+J5+J6)>0,('Profit & Loss'!J10+'Profit & Loss'!J9)*2/(I4+I5+I6+J4+J5+J6),"") -> 0.40468196 | K24: =IF((J4+J5+J6+K4+K5+K6)>0,('Profit & Loss'!K10+'Profit & Loss'!K9)*2/(J4+J5+J6+K4+K5+K6),"") -> 0.37925394

Sheet Cash Flow
A1: ='Balance Sheet'!A1 -> INFOSYS LTD | E1: =UPDATE | J1: SCREENER.IN
A3: Narration | B3: ='Data Sheet'!B81 -> 42460 | C3: ='Data Sheet'!C81 -> 42825 | D3: ='Data Sheet'!D81 -> 43190 | E3: ='Data Sheet'!E81 -> 43555 | F3: ='Data Sheet'!F81 -> 43921 | G3: ='Data Sheet'!G81 -> 44286 | H3: ='Data Sheet'!H81 -> 44651 | I3: ='Data Sheet'!I81 -> 45016 | ... K3: ='Data Sheet'!K81 -> 45747
A4: Cash from Operating Activity | B4: ='Data Sheet'!B82 -> 10028 | C4: ='Data Sheet'!C82 -> 11531 | D4: ='Data Sheet'!D82 -> 13218 | E4: ='Data Sheet'!E82 -> 14841 | F4: ='Data Sheet'!F82 -> 17003 | G4: ='Data Sheet'!G82 -> 23224 | H4: ='Data Sheet'!H82 -> 23885 | I4: ='Data Sheet'!I82 -> 22467 | ... K4: ='Data Sheet'!K82 -> 35694
A5: Cash from Investing Activity | B5: ='Data Sheet'!B83 -> -885 | C5: ='Data Sheet'!C83 -> -14664 | D5: ='Data Sheet'!D83 -> 4533 | E5: ='Data Sheet'!E83 -> -632 | F5: ='Data Sheet'!F83 -> -331 | G5: ='Data Sheet'!G83 -> -7373 | H5: ='Data Sheet'!H83 -> -6485 | I5: ='Data Sheet'!I83 -> -1071 | ... K5: ='Data Sheet'!K83 -> -1864
A6: Cash from Financing Activity | B6: ='Data Sheet'!B84 -> -6813 | C6: ='Data Sheet'!C84 -> -6939 | D6: ='Data Sheet'!D84 -> -20505 | E6: ='Data Sheet'!E84 -> -14512 | F6: ='Data Sheet'!F84 -> -17591 | G6: ='Data Sheet'!G84 -> -9786 | H6: ='Data Sheet'!H84 -> -24642 | I6: ='Data Sheet'!I84 -> -26695 | ... K6: ='Data Sheet'!K84 -> -24161
A7: Net Cash Flow | B7: ='Data Sheet'!B85 -> 2330 | C7: ='Data Sheet'!C85 -> -10072 | D7: ='Data Sheet'!D85 -> -2754 | E7: ='Data Sheet'!E85 -> -303 | F7: ='Data Sheet'!F85 -> -919 | G7: ='Data Sheet'!G85 -> 6065 | H7: ='Data Sheet'!H85 -> -7242 | I7: ='Data Sheet'!I85 -> -5299 | ... K7: ='Data Sheet'!K85 -> 9669

Sheet Customization
A1: How to use it?
A3: You can customize this workbook as you want.
B4: You can add custom formating, add conditional formating, add your own formulas… do ANYTHING.
B5: Please don't edit the "Data Sheet" only.
A7: After customization, you can upload this back on Screener.
B8: Upload on: | C8: https://www.screener.in/excel/
A10: Download your customized workbooks now onwards.
B11: Now whenever you will "Export to excel" from Screener, it will export your customized file.
A14: TESTING:
B15: This is a testing feature currently.
B16: You can report any formula errors on the worksheet at: support@screener.in

Sheet Data Sheet
A1: COMPANY NAME | B1: INFOSYS LTD | E1: =IF(B2<>B3, "A NEW VERSION OF THE WORKSHEET IS AVAILABLE", "")
A2: LATEST VERSION | B2: 2.1 | E2: PLEASE DO NOT MAKE ANY CHANGES TO THIS SHEET
A3: CURRENT VERSION | B3: 2.1
A5: META
A6: Number of shares | B6: =IF(B9>0, B9/B8, 0) -> 405.53911
A7: Face Value | B7: 5
A8: Current Price | B8: 1300.1
A9: Market Capitalization | B9: 527241.4
A15: PROFIT & LOSS
A16: Report Date | B16: 42460 | C16: 42825 | D16: 43190 | E16: 43555 | F16: 43921 | G16: 44286 | H16: 44651 | I16: 45016 | J16: 45382 | K16: 45747
A17: Sales | B17: 62441 | C17: 68484 | D17: 70522 | E17: 82675 | F17: 90791 | G17: 100472 | H17: 121641 | I17: 146767 | J17: 153670 | K17: 162990
A18: Raw Material Cost
A19: Change in Inventory
A20: Power and Fuel | B20: 217 | C20: 228 | D20: 207 | E20: 221 | F20: 229 | G20: 143 | H20: 132 | I20: 176 | J20: 199 | K20: 222
A21: Other Mfr. Exp | B21: 5860 | C21: 6712 | D21: 7286 | E21: 9902 | F21: 11086 | G21: 12800 | H21: 20690 | I21: 26330 | J21: 27195 | K21: 30395
A22: Employee Cost | B22: 34415 | C22: 37669 | D22: 38902 | E22: 45323 | F22: 50895 | G22: 55547 | H22: 63997 | I22: 78374 | J22: 82636 | K22: 85968
A23: Selling and admin | B23: 4441 | C23: 4584 | D23: 4585 | E23: 5553 | F23: 5375 | G23: 3194 | H23: 4305 | I23: 5300 | J23: 5705 | K23: 6039
A24: Other Expenses | B24: 429 | C24: 687 | D24: 720 | E24: 1506 | F24: 939 | G24: 899 | H24: 1026 | I24: 1457 | J24: 1510 | K24: 1130
A25: Other Income | B25: 3120 | C25: 3050 | D25: 3311 | E25: 2882 | F25: 2803 | G25: 2201 | H25: 2295 | I25: 2701 | J25: 4711 | K25: 3600
A26: Depreciation | B26: 1459 | C26: 1703 | D26: 1863 | E26: 2011 | F26: 2893 | G26: 3267 | H26: 3476 | I26: 4225 | J26: 4678 | K26: 4812
A27: Interest | F27: 170 | G27: 195 | H27: 200 | I27: 284 | J27: 470 | K27: 416
A28: Profit before tax | B28: 18740 | C28: 19951 | D28: 20270 | E28: 21041 | F28: 22007 | G28: 26628 | H28: 30110 | I28: 33322 | J28: 35988 | K28: 37608
A29: Tax | B29: 5251 | C29: 5598 | D29: 4241 | E29: 5631 | F29: 5368 | G29: 7205 | H29: 7964 | I29: 9214 | J29: 9740 | K29: 10858
A30: Net profit | B30: 13489 | C30: 14353 | D30: 16029 | E30: 15404 | F30: 16594 | G30: 19351 | H30: 22110 | I30: 24095 | J30: 26233 | K30: 26713
A31: Dividend Amount | B31: 5548.4 | C31: 5891.6 | D31: 9465.6 | E31: 9222.5 | F31: 7427 | G31: 11469.6 | H31: 13007.6 | I31: 14069.2 | J31: 19053.2 | K31: 17827.8
A40: Quarters
A41: Report Date | B41: 45199 | C41: 45291 | D41: 45382 | E41: 45473 | F41: 45565 | G41: 45657 | H41: 45747 | I41: 45838 | J41: 45930 | K41: 46022
A42: Sales | B42: 38994 | C42: 38821 | D42: 37923 | E42: 39315 | F42: 40986 | G42: 41764 | H42: 40925 | I42: 42279 | J42: 44490 | K42: 45479
A43: Expenses | B43: 29554 | C43: 29684 | D43: 29139 | E43: 29878 | F43: 31177 | G43: 31649 | H43: 31051 | I43: 32336 | J43: 33955 | K43: 34845
A44: Other Income | B44: 632 | C44: 789 | D44: 2729 | E44: 838 | F44: 712 | G44: 859 | H44: 1190 | I44: 1042 | J44: 982 | K44: -150
A45: Depreciation | B45: 1166 | C45: 1176 | D45: 1163 | E45: 1149 | F45: 1160 | G45: 1203 | H45: 1299 | I45: 1140 | J45: 1182 | K45: 1155
A46: Interest | B46: 138 | C46: 131 | D46: 110 | E46: 105 | F46: 108 | G46: 101 | H46: 102 | I46: 105 | J46: 106 | K46: 100
A47: Profit before tax | B47: 8768 | C47: 8619 | D47: 10240 | E47: 9021 | F47: 9253 | G47: 9670 | H47: 9663 | I47: 9740 | J47: 10229 | K47: 9229
A48: Tax | B48: 2553 | C48: 2506 | D48: 2265 | E48: 2647 | F48: 2737 | G48: 2848 | H48: 2625 | I48: 2816 | J48: 2854 | K48: 2563
A49: Net profit | B49: 6212 | C49: 6106 | D49: 7969 | E49: 6368 | F49: 6506 | G49: 6806 | H49: 7033 | I49: 6921 | J49: 7364 | K49: 6654
A50: Operating Profit | B50: 9440 | C50: 9137 | D50: 8784 | E50: 9437 | F50: 9809 | G50: 10115 | H50: 9874 | I50: 9943 | J50: 10535 | K50: 10634
A55: BALANCE SHEET
A56: Report Date | B56: 42460 | C56: 42825 | D56: 43190 | E56: 43555 | F56: 43921 | G56: 44286 | H56: 44651 | I56: 45016 | J56: 45382 | K56: 45747
A57: Equity Share Capital | B57: 1144 | C57: 1144 | D57: 1088 | E57: 2170 | F57: 2122 | G57: 2124 | H57: 2098 | I57: 2069 | J57: 2071 | K57: 2073
A58: Reserves | B58: 60600 | C58: 67838 | D58: 63835 | E58: 62778 | F58: 63328 | G58: 74227 | H58: 73252 | I58: 73338 | J58: 86045 | K58: 93745
...

Sheet Assumption Data
C2: 44651 | D2: 45016 | E2: 45382 | F2: 45747 | I2: 44651 | J2: 45016 | K2: 45382 | L2: 45747 | M2: CAGR | P2: Assumptions | Q2: CAGR
B3: Sales | C3: 121641 | D3: 146767 | E3: 153670 | F3: 162990 | H3: Sales | J3: =D3/C3-1 -> 0.20655864 | K3: =E3/D3-1 -> 0.047033734 | L3: =F3/E3-1 -> 0.060649444 | M3: =AVERAGE(I3:L3) -> 0.10474727 | P3: Sales | Q3: 0.1
B4: Expenses | C4: 90150 | D4: 111637 | E4: 117245 | F4: 123754 | H4: Expenses | I4: =C4/C3 -> 0.74111525 | J4: =D4/D3 -> 0.76064102 | K4: =E4/E3 -> 0.7629661 | L4: =F4/F3 -> 0.75927358 | M4: =AVERAGE(I4:L4) -> 0.75599898 | P4: Expenses % sales | Q4: 0.76
B5: Operating Profit | C5: 31491 | D5: 35130 | E5: 36425 | F5: 39236 | H5: Operating Profit | P5: Depreciation % sales | Q5: 0.03
B6: Other Income | C6: 2295 | D6: 2701 | E6: 4711 | F6: 3600 | H6: Other Income | P6: Tax | Q6: 0.28
B7: Depreciation | C7: 3476 | D7: 4225 | E7: 4678 | F7: 4812 | H7: Depreciation | I7: =C7/C3 -> 0.028575891 | J7: =D7/D3 -> 0.028787125 | K7: =E7/E3 -> 0.030441856 | L7: =F7/F3 -> 0.029523284 | M7: =AVERAGE(I7:L7) -> 0.029332039
B8: Interest | C8: 200 | D8: 284 | E8: 470 | F8: 416 | H8: Interest | P8: Share capital | Q8: 2073
B9: Profit before tax | C9: 30110 | D9: 33322 | E9: 35988 | F9: 37608 | H9: Profit before tax | P9: Borrowing | Q9: 0.18
B10: Tax | C10: 7964 | D10: 9214 | E10: 9740 | F10: 10858 | H10: Tax | I10: =C10/C9 -> 0.26449684 | J10: =D10/D9 -> 0.27651401 | K10: =E10/E9 -> 0.27064577 | L10: =F10/F9 -> 0.28871517 | M10: =AVERAGE(I10:L10) -> 0.27509295 | P10: Others liabilities | Q10: 0.28
B11: Net profit | C11: 22110 | D11: 24095 | E11: 26233 | F11: 26713 | H11: Net profit | P11: Dividend % sales | Q11: 0.64
P13: CWIP | Q13: 0.05
B14: Narration | C14: 44651 | D14: 45016 | E14: 45382 | F14: 45747 | H14: Narration | I14: 44651 | J14: 45016 | K14: 45382 | L14: 45747 | M14: CAGR | P14: Investments | Q14: 0.06
B15: Equity Share Capital | C15: 2098 | D15: 2069 | E15: 2071 | F15: 2073 | H15: Equity Share Capital | I15: =C15 -> 2098 | J15: =D15 -> 2069 | K15: =E15 -> 2071 | L15: =F15 -> 2073 | M15: =L15 -> 2073 | P15: Others Assets % sales | Q15: 0.45
B16: Reserves | C16: 73252 | D16: 73338 | E16: 86045 | F16: 93745 | H16: Reserves | P16: Capex % sales | Q16: 0.04
B17: Borrowings | C17: 5474 | D17: 8299 | E17: 8359 | F17: 8227 | H17: Borrowings | J17: =D17/C17-1 -> 0.516076 | K17: =E17/D17-1 -> 0.0072297867 | L17: =F17/E17-1 -> -0.015791363 | M17: =AVERAGE(I17:L17) -> 0.16917147
B18: Other Liabilities | C18: 35905 | D18: 40890 | E18: 40885 | F18: 43750 | H18: Other Liabilities | I18: =C18/C3 -> 0.29517186 | J18: =D18/D3 -> 0.27860486 | K18: =E18/E3 -> 0.26605714 | L18: =F18/F3 -> 0.26842138 | M18: =AVERAGE(I18:L18) -> 0.27706381
B19: Total | C19: =SUM(C15:C18) -> 116729 | D19: =SUM(D15:D18) -> 124596 | E19: =SUM(E15:E18) -> 137360 | F19: =SUM(F15:F18) -> 147795 | H19: Total
H21: Net Block
H22: Capital Work in Progress | J22: =D25/C25-1 -> -0.30769231 | K22: =E25/D25-1 -> 0.017361111 | L22: =F25/E25-1 -> 1.778157 | M22: =AVERAGE(I22:L22) -> 0.49594193
B23: Cash | C23: =C42 -> 13207 | D23: =D42 -> 15466 | E23: =E42 -> 10692 | F23: =F42 -> 12592 | H23: Investments | J23: =D26/C26-1 -> -0.041625664 | K23: =E26/D26-1 -> 0.26414416 | L23: =F26/E26-1 -> -0.043942655 | M23: =AVERAGE(I23:L23) -> 0.059525281
B24: Net Block | C24: 25800 | D24: 29225 | E24: 27622 | F24: 30961 | H24: Other Assets | J24: =C27/C3 -> 0.46844403 | K24: =D27/D3 -> 0.40975832 | L24: =E27/E3 -> 0.48239734 | M24: =AVERAGE(I24:L24) -> 0.45353323
B25: Capital Work in Progress | C25: 416 | D25: 288 | E25: 293 | F25: 814 | H25: Total
B26: Investments | C26: 20324 | D26: 19478 | E26: 24623 | F26: 23541
B27: Other Assets | C27: =C38 -> 56982 | D27: =D38 -> 60139 | E27: =E38 -> 74130 | F27: =F38 -> 79887 | H27: Working Capital
B28: Total | C28: =SUM(C23:C27) -> 116729 | D28: =SUM(D23:D27) -> 124596 | E28: =SUM(E23:E27) -> 137360 | F28: =SUM(F23:F27) -> 147795 | H28: Debtors
H29: Inventory
B30: Working Capital | C30: 34284 | D30: 34715 | E30: 43937 | F30: 48729
B31: Debtors | C31: 22698 | D31: 25424 | E31: 30193 | F31: 31158
B32: Inventory | C32: 0 | D32: 0 | E32: 0 | F32: 0
I33: 44651 | J33: 45016 | K33: 45382 | L33: 45747 | M33: CAGR
B34: Balance Check | C34: =C28-C19 -> 0 | D34: =D28-D19 -> 0 | E34: =E28-E19 -> 0 | F34: =F28-F19 -> 0 | H34: Net profit | I34: 22110 | J34: 24095 | K34: 26233 | L34: 26713
H35: Dividend | I35: 13007.6 | J35: 14069.2 | K35: 19053.2 | L35: 17827.8
H36: Dividend % of sales | I36: =I35/I34 -> 0.58831298 | J36: =J35/J34 -> 0.58390537 | K36: =K35/K34 -> 0.72630656 | L36: =L35/L34 -> 0.66738292 | M36: =AVERAGE(I36:L36) -> 0.64147696
B38: Other assets | C38: =SUM(C30:C32) -> 56982 | D38: =SUM(D30:D32) -> 60139 | E38: =SUM(E30:E32) -> 74130 | F38: =SUM(F30:F32) -> 79887
I39: 44651 | J39: 45016 | K39: 45382 | L39: 45747
H40: End | I40: =C24 -> 25800 | J40: =D24 -> 29225 | K40: =E24 -> 27622 | L40: =F24 -> 30961
C41: 70189 | D41: 75605 | E41: 84822 | F41: 92479 | H41: Beginning | J41: =-I40 -> -25800 | K41: =-J40 -> -29225 | L41: =-K40 -> -27622
B42: cash | C42: =C41-C38 -> 13207 | D42: =D41-D38 -> 15466 | E42: =E41-E38 -> 10692 | F42: =F41-F38 -> 12592 | H42: Dep | J42: =C7 -> 3476 | K42: =D7 -> 4225 | L42: =E7 -> 4678
H43: Capex | J43: =SUM(J40:J42) -> 6901 | K43: =SUM(K40:K42) -> 2622 | L43: =SUM(L40:L42) -> 8017
H44: % of sales | J44: =J43/D3 -> 0.047020107 | K44: =K43/E3 -> 0.017062537 | L44: =L43/F3 -> 0.049187067 | M44: =AVERAGE(J44:L44) -> 0.03775657

Sheet 1M2026-TSM
B3: INFOSYS LTD - THREE STATEMENT MODEL DASHBOARD (2026-2029)
B5: Income Statement | C5: 2025 | D5: 2026 | E5: 2027 | F5: 2028 | G5: 2029 | I5: Supporting Schedule
B6: Sales | C6: 162990 | D6: =C6*1.1 -> 179289 | E6: =D6*1.1 -> 197217.9 | F6: =E6*1.1 -> 216939.69 | G6: =F6*1.1 -> 238633.66 | J6: 2025 | K6: 2026 | L6: 2027 | M6: 2028 | N6: 2029
B7: Expenses | C7: 123754 | D7: =-D6*0.7 -> -125502.3 | E7: =-E6*0.7 -> -138052.53 | F7: =-F6*0.7 -> -151857.78 | G7: =-G6*0.7 -> -167043.56 | I7: Reserve
B8: Operating Profit | C8: 39236 | D8: =SUM(D6:D7) -> 53786.7 | E8: =SUM(E6:E7) -> 59165.37 | F8: =SUM(F6:F7) -> 65081.907 | G8: =SUM(G6:G7) -> 71590.098 | I8: Beginning | K8: =J11 -> 93745 | L8: =K11 -> 106292.36 | M8: =L11 -> 120094.46 | N8: =M11 -> 135276.77
B9: Other Income | C9: 3600 | I9: Net Income | K9: =D14 -> 34853.782 | L9: =E14 -> 38339.16 | M9: =F14 -> 42173.076 | N9: =G14 -> 46390.383
B10: Depreciation | C10: 4812 | D10: =-D6*0.03 -> -5378.67 | E10: =-E6*0.03 -> -5916.537 | F10: =-F6*0.03 -> -6508.1907 | G10: =-G6*0.03 -> -7159.0098 | I10: Dividend | K10: =-K9*0.64 -> -22306.42 | L10: =-L9*0.64 -> -24537.062 | M10: =-M9*0.64 -> -26990.768 | N10: =-N9*0.64 -> -29689.845
B11: Interest | C11: 416 | I11: End | J11: 93745 | K11: =SUM(K8:K10) -> 106292.36 | L11: =SUM(L8:L10) -> 120094.46 | M11: =SUM(M8:M10) -> 135276.77 | N11: =SUM(N8:N10) -> 151977.3
B12: Profit before tax | C12: 37608 | D12: =SUM(D8:D11) -> 48408.03 | E12: =SUM(E8:E11) -> 53248.833 | F12: =SUM(F8:F11) -> 58573.716 | G12: =SUM(G8:G11) -> 64431.088
B13: Tax | C13: 10858 | D13: =-D12*0.28 -> -13554.248 | E13: =-E12*0.28 -> -14909.673 | F13: =-F12*0.28 -> -16400.641 | G13: =-G12*0.28 -> -18040.705
B14: Net profit | C14: 26713 | D14: =SUM(D12:D13) -> 34853.782 | E14: =SUM(E12:E13) -> 38339.16 | F14: =SUM(F12:F13) -> 42173.076 | G14: =SUM(G12:G13) -> 46390.383
I15: Net Block | J15: 2025 | K15: 2026 | L15: 2027 | M15: 2028 | N15: 2029
B17: Balance Sheet | C17: 2025 | D17: 2026 | E17: 2027 | F17: 2028 | G17: 2029 | I17: Beginning Net Block | K17: =J20 -> 30961 | L17: =K20 -> 32753.89 | M17: =L20 -> 34726.069 | N17: =M20 -> 36895.466
B18: Equity Share Capital | C18: 2073 | D18: =C18 -> 2073 | E18: =D18 -> 2073 | F18: =E18 -> 2073 | G18: =F18 -> 2073 | I18: capex | K18: =D6*0.04 -> 7171.56 | L18: =E6*0.04 -> 7888.716 | M18: =F6*0.04 -> 8677.5876 | N18: =G6*0.04 -> 9545.3464
B19: Reserves | C19: 93745 | D19: =K11 -> 106292.36 | E19: =L11 -> 120094.46 | F19: =M11 -> 135276.77 | G19: =N11 -> 151977.3 | I19: Depreciation | K19: =D10 -> -5378.67 | L19: =E10 -> -5916.537 | M19: =F10 -> -6508.1907 | N19: =G10 -> -7159.0098
B20: Borrowings | C20: 8227 | D20: =C20*1.18 -> 9707.86 | E20: =D20*1.18 -> 11455.275 | F20: =E20*1.18 -> 13517.224 | G20: =F20*1.18 -> 15950.325 | I20: End Net Block | J20: 30961 | K20: =SUM(K17:K19) -> 32753.89 | L20: =SUM(L17:L19) -> 34726.069 | M20: =SUM(M17:M19) -> 36895.466 | N20: =SUM(N17:N19) -> 39281.802
B21: Other Liabilities | C21: 43750 | D21: =D6*0.28 -> 50200.92 | E21: =E6*0.28 -> 55221.012 | F21: =F6*0.28 -> 60743.113 | G21: =G6*0.28 -> 66817.425
B22: Total | C22: =SUM(C18:C21) -> 147795 | D22: =SUM(D18:D21) -> 168274.14 | E22: =SUM(E18:E21) -> 188843.75 | F22: =SUM(F18:F21) -> 211610.1 | G22: =SUM(G18:G21) -> 236818.05
I23: Assumptions | J23: CAGR
I24: Sales | J24: 0.1
B25: Cash | C25: 12592 | D25: =D54 -> 28665.741 | E25: =E54 -> 37087.454 | F25: =F54 -> 46306.82 | G25: =G54 -> 56310.259 | I25: Expenses % sales | J25: 0.76
B26: Net Block | C26: 30961 | D26: =K20 -> 32753.89 | E26: =L20 -> 34726.069 | F26: =M20 -> 36895.466 | G26: =N20 -> 39281.802 | I26: Depreciation % sales | J26: 0.03
B27: Capital Work in Progress | C27: 814 | D27: =C27*1.5 -> 1221 | E27: =D27*1.5 -> 1831.5 | F27: =E27*1.5 -> 2747.25 | G27: =F27*1.5 -> 4120.875 | I27: Tax | J27: 0.28
B28: Investments | C28: 23541 | D28: =C28*1.06 -> 24953.46 | E28: =D28*1.06 -> 26450.668 | F28: =E28*1.06 -> 28037.708 | G28: =F28*1.06 -> 29719.97
B29: Other Assets | C29: 79887 | D29: =D6*0.45 -> 80680.05 | E29: =E6*0.45 -> 88748.055 | F29: =F6*0.45 -> 97622.861 | G29: =G6*0.45 -> 107385.15 | I29: Share capital | J29: 2073
B30: Total | C30: =SUM(C25:C29) -> 147795 | D30: =SUM(D25:D29) -> 168274.14 | E30: =SUM(E25:E29) -> 188843.75 | F30: =SUM(F25:F29) -> 211610.1 | G30: =SUM(G25:G29) -> 236818.05 | I30: Borrowing | J30: 0.18
I31: Others liabilities | J31: 0.28
I32: Dividend % sales | J32: 0.64
B33: Balance Check | C33: =C22-C30 -> 0 | D33: =D22-D30 -> 0 | E33: =E22-E30 -> 0 | F33: =F22-F30 -> 0 | G33: =G22-G30 -> 0
I34: CWIP | J34: 0.05
I35: Investments | J35: 0.06
B36: Cash Flow Statement | C36: 2025 | D36: 2026 | E36: 2027 | F36: 2028 | G36: 2029 | I36: Others Assets % sales | J36: 0.45
B37: Net income | D37: =D14 -> 34853.782 | E37: =E14 -> 38339.16 | F37: =F14 -> 42173.076 | G37: =G14 -> 46390.383 | I37: Capex % sales | J37: 0.04
B38: Dep | D38: =-D10 -> 5378.67 | E38: =-E10 -> 5916.537 | F38: =-F10 -> 6508.1907 | G38: =-G10 -> 7159.0098
B39: Others Assets | D39: =C29-D29 -> -793.05 | E39: =D29-E29 -> -8068.005 | F39: =E29-F29 -> -8874.8055 | G39: =F29-G29 -> -9762.2861
B40: Others Liabilities | D40: =D21-C21 -> 6450.92 | E40: =E21-D21 -> 5020.092 | F40: =F21-E21 -> 5522.1012 | G40: =G21-F21 -> 6074.3113
B41: Change In Op | D41: =SUM(D37:D40) -> 45890.322 | E41: =SUM(E37:E40) -> 41207.784 | F41: =SUM(F37:F40) -> 45328.562 | G41: =SUM(G37:G40) -> 49861.418
B43: Capex | D43: =-K18 -> -7171.56 | E43: =-L18 -> -7888.716 | F43: =-M18 -> -8677.5876 | G43: =-N18 -> -9545.3464
B44: CWIP | D44: =C27-D27 -> -407 | E44: =D27-E27 -> -610.5 | F44: =E27-F27 -> -915.75 | G44: =F27-G27 -> -1373.625
B45: Investments | D45: =C28-D28 -> -1412.46 | E45: =D28-E28 -> -1497.2076 | F45: =E28-F28 -> -1587.0401 | G45: =F28-G28 -> -1682.2625
...

Sheet Assumption Dashboard
B2: INFOSYS LTD - ASSUMPTION DATA DASHBOARD
B3: PROFIT & LOSS - HISTORICAL | H3: GROWTH ANALYSIS | O3: MODEL ASSUMPTIONS
C4: 46103 | D4: 46104 | E4: 46105 | F4: 46106 | I4: 46103 | J4: 46104 | K4: 46105 | L4: 46106 | M4: CAGR | O4: Assumptions | P4: Value
B5: Sales | C5: ='Assumption Data'!C3 -> 121641 | D5: ='Assumption Data'!D3 -> 146767 | E5: ='Assumption Data'!E3 -> 153670 | F5: ='Assumption Data'!F3 -> 162990 | H5: Sales | I5: ='Assumption Data'!I3 -> 0 | J5: ='Assumption Data'!J3 -> 0.20655864 | K5: ='Assumption Data'!K3 -> 0.047033734 | L5: ='Assumption Data'!L3 -> 0.060649444 | M5: ='Assumption Data'!M3 -> 0.10474727 | O5: Sales CAGR | P5: ='Assumption Data'!Q3 -> 0.1
B6: Expenses | C6: ='Assumption Data'!C4 -> 90150 | D6: ='Assumption Data'!D4 -> 111637 | E6: ='Assumption Data'!E4 -> 117245 | F6: ='Assumption Data'!F4 -> 123754 | H6: Expenses | I6: ='Assumption Data'!I4 -> 0.74111525 | J6: ='Assumption Data'!J4 -> 0.76064102 | K6: ='Assumption Data'!K4 -> 0.7629661 | L6: ='Assumption Data'!L4 -> 0.75927358 | M6: ='Assumption Data'!M4 -> 0.75599898 | O6: Expenses % sales | P6: ='Assumption Data'!Q4 -> 0.76
B7: Operating Profit | C7: ='Assumption Data'!C5 -> 31491 | D7: ='Assumption Data'!D5 -> 35130 | E7: ='Assumption Data'!E5 -> 36425 | F7: ='Assumption Data'!F5 -> 39236 | H7: Operating Profit | I7: ='Assumption Data'!I5 -> 0 | J7: ='Assumption Data'!J5 -> 0 | K7: ='Assumption Data'!K5 -> 0 | L7: ='Assumption Data'!L5 -> 0 | M7: ='Assumption Data'!M5 -> 0 | O7: Depreciation % sales | P7: ='Assumption Data'!Q5 -> 0.03
B8: Other Income | C8: ='Assumption Data'!C6 -> 2295 | D8: ='Assumption Data'!D6 -> 2701 | E8: ='Assumption Data'!E6 -> 4711 | F8: ='Assumption Data'!F6 -> 3600 | H8: Other Income | I8: ='Assumption Data'!I6 -> 0 | J8: ='Assumption Data'!J6 -> 0 | K8: ='Assumption Data'!K6 -> 0 | L8: ='Assumption Data'!L6 -> 0 | M8: ='Assumption Data'!M6 -> 0 | O8: Tax Rate | P8: ='Assumption Data'!Q6 -> 0.28
B9: Depreciation | C9: ='Assumption Data'!C7 -> 3476 | D9: ='Assumption Data'!D7 -> 4225 | E9: ='Assumption Data'!E7 -> 4678 | F9: ='Assumption Data'!F7 -> 4812 | H9: Depreciation | I9: ='Assumption Data'!I7 -> 0.028575891 | J9: ='Assumption Data'!J7 -> 0.028787125 | K9: ='Assumption Data'!K7 -> 0.030441856 | L9: ='Assumption Data'!L7 -> 0.029523284 | M9: ='Assumption Data'!M7 -> 0.029332039
B10: Interest | C10: ='Assumption Data'!C8 -> 200 | D10: ='Assumption Data'!D8 -> 284 | E10: ='Assumption Data'!E8 -> 470 | F10: ='Assumption Data'!F8 -> 416 | H10: Interest | I10: ='Assumption Data'!I8 -> 0 | J10: ='Assumption Data'!J8 -> 0 | K10: ='Assumption Data'!K8 -> 0 | L10: ='Assumption Data'!L8 -> 0 | M10: ='Assumption Data'!M8 -> 0 | O10: Share capital | P10: ='Assumption Data'!Q8 -> 2073
B11: Profit before tax | C11: ='Assumption Data'!C9 -> 30110 | D11: ='Assumption Data'!D9 -> 33322 | E11: ='Assumption Data'!E9 -> 35988 | F11: ='Assumption Data'!F9 -> 37608 | H11: Profit before tax | I11: ='Assumption Data'!I9 -> 0 | J11: ='Assumption Data'!J9 -> 0 | K11: ='Assumption Data'!K9 -> 0 | L11: ='Assumption Data'!L9 -> 0 | M11: ='Assumption Data'!M9 -> 0 | O11: Borrowing Growth | P11: ='Assumption Data'!Q9 -> 0.18
B12: Tax | C12: ='Assumption Data'!C10 -> 7964 | D12: ='Assumption Data'!D10 -> 9214 | E12: ='Assumption Data'!E10 -> 9740 | F12: ='Assumption Data'!F10 -> 10858 | H12: Tax | I12: ='Assumption Data'!I10 -> 0.26449684 | J12: ='Assumption Data'!J10 -> 0.27651401 | K12: ='Assumption Data'!K10 -> 0.27064577 | L12: ='Assumption Data'!L10 -> 0.28871517 | M12: ='Assumption Data'!M10 -> 0.27509295 | O12: Others liabilities % | P12: ='Assumption Data'!Q10 -> 0.28
B13: Net profit | C13: ='Assumption Data'!C11 -> 22110 | D13: ='Assumption Data'!D11 -> 24095 | E13: ='Assumption Data'!E11 -> 26233 | F13: ='Assumption Data'!F11 -> 26713 | H13: Net profit | I13: ='Assumption Data'!I11 -> 0 | J13: ='Assumption Data'!J11 -> 0 | K13: ='Assumption Data'!K11 -> 0 | L13: ='Assumption Data'!L11 -> 0 | M13: ='Assumption Data'!M11 -> 0 | O13: Dividend % Net Income | P13: ='Assumption Data'!Q11 -> 0.64
B14: BALANCE SHEET - LIABILITIES | H14: LIABILITY RATIOS
B15: Narration | C15: 46103 | D15: 46104 | E15: 46105 | F15: 46106 | H15: Narration | I15: 46103 | J15: 46104 | K15: 46105 | L15: 46106 | M15: CAGR | O15: CWIP Growth | P15: ='Assumption Data'!Q13 -> 0.05
B16: Equity Share Capital | C16: ='Assumption Data'!C15 -> 2098 | D16: ='Assumption Data'!D15 -> 2069 | E16: ='Assumption Data'!E15 -> 2071 | F16: ='Assumption Data'!F15 -> 2073 | H16: Equity Share Capital | I16: ='Assumption Data'!I15 -> 2098 | J16: ='Assumption Data'!J15 -> 2069 | K16: ='Assumption Data'!K15 -> 2071 | L16: ='Assumption Data'!L15 -> 2073 | M16: ='Assumption Data'!M15 -> 2073 | O16: Investments Growth | P16: ='Assumption Data'!Q14 -> 0.06
B17: Reserves | C17: ='Assumption Data'!C16 -> 73252 | D17: ='Assumption Data'!D16 -> 73338 | E17: ='Assumption Data'!E16 -> 86045 | F17: ='Assumption Data'!F16 -> 93745 | H17: Reserves | I17: ='Assumption Data'!I16 -> 0 | J17: ='Assumption Data'!J16 -> 0 | K17: ='Assumption Data'!K16 -> 0 | L17: ='Assumption Data'!L16 -> 0 | M17: ='Assumption Data'!M16 -> 0 | O17: Others Assets % sales | P17: ='Assumption Data'!Q15 -> 0.45
B18: Borrowings | C18: ='Assumption Data'!C17 -> 5474 | D18: ='Assumption Data'!D17 -> 8299 | E18: ='Assumption Data'!E17 -> 8359 | F18: ='Assumption Data'!F17 -> 8227 | H18: Borrowings | I18: ='Assumption Data'!I17 -> 0 | J18: ='Assumption Data'!J17 -> 0.516076 | K18: ='Assumption Data'!K17 -> 0.0072297867 | L18: ='Assumption Data'!L17 -> -0.015791363 | M18: ='Assumption Data'!M17 -> 0.16917147 | O18: Capex % sales | P18: ='Assumption Data'!Q16 -> 0.04
B19: Other Liabilities | C19: ='Assumption Data'!C18 -> 35905 | D19: ='Assumption Data'!D18 -> 40890 | E19: ='Assumption Data'!E18 -> 40885 | F19: ='Assumption Data'!F18 -> 43750 | H19: Other Liabilities | I19: ='Assumption Data'!I18 -> 0.29517186 | J19: ='Assumption Data'!J18 -> 0.27860486 | K19: ='Assumption Data'!K18 -> 0.26605714 | L19: ='Assumption Data'!L18 -> 0.26842138 | M19: ='Assumption Data'!M18 -> 0.27706381
B20: Total | C20: ='Assumption Data'!C19 -> 116729 | D20: ='Assumption Data'!D19 -> 124596 | E20: ='Assumption Data'!E19 -> 137360 | F20: ='Assumption Data'!F19 -> 147795
B21: BALANCE SHEET - ASSETS | H21: ASSET RATIOS
B22: Assets | C22: 46103 | D22: 46104 | E22: 46105 | F22: 46106 | H22: Asset Ratios | I22: 46103 | J22: 46104 | K22: 46105 | L22: 46106 | M22: CAGR
B23: Cash | C23: ='Assumption Data'!C23 -> 13207 | D23: ='Assumption Data'!D23 -> 15466 | E23: ='Assumption Data'!E23 -> 10692 | F23: ='Assumption Data'!F23 -> 12592 | H23: Net Block | I23: ='Assumption Data'!I21 -> 0 | J23: ='Assumption Data'!J21 -> 0 | K23: ='Assumption Data'!K21 -> 0 | L23: ='Assumption Data'!L21 -> 0 | M23: ='Assumption Data'!M21 -> 0
B24: Net Block | C24: ='Assumption Data'!C24 -> 25800 | D24: ='Assumption Data'!D24 -> 29225 | E24: ='Assumption Data'!E24 -> 27622 | F24: ='Assumption Data'!F24 -> 30961 | H24: Capital Work in Progress | I24: ='Assumption Data'!I22 -> 0 | J24: ='Assumption Data'!J22 -> -0.30769231 | K24: ='Assumption Data'!K22 -> 0.017361111 | L24: ='Assumption Data'!L22 -> 1.778157 | M24: ='Assumption Data'!M22 -> 0.49594193
B25: Capital Work in Progress | C25: ='Assumption Data'!C25 -> 416 | D25: ='Assumption Data'!D25 -> 288 | E25: ='Assumption Data'!E25 -> 293 | F25: ='Assumption Data'!F25 -> 814 | H25: Investments | I25: ='Assumption Data'!I23 -> 0 | J25: ='Assumption Data'!J23 -> -0.041625664 | K25: ='Assumption Data'!K23 -> 0.26414416 | L25: ='Assumption Data'!L23 -> -0.043942655 | M25: ='Assumption Data'!M23 -> 0.059525281
B26: Investments | C26: ='Assumption Data'!C26 -> 20324 | D26: ='Assumption Data'!D26 -> 19478 | E26: ='Assumption Data'!E26 -> 24623 | F26: ='Assumption Data'!F26 -> 23541 | H26: Other Assets | I26: ='Assumption Data'!I24 -> 0 | J26: ='Assumption Data'!J24 -> 0.46844403 | K26: ='Assumption Data'!K24 -> 0.40975832 | L26: ='Assumption Data'!L24 -> 0.48239734 | M26: ='Assumption Data'!M24 -> 0.45353323
B27: Other Assets | C27: ='Assumption Data'!C27 -> 56982 | D27: ='Assumption Data'!D27 -> 60139 | E27: ='Assumption Data'!E27 -> 74130 | F27: ='Assumption Data'!F27 -> 79887
B28: Total Assets | C28: =SUM(C23:C27) -> 116729 | D28: =SUM(D23:D27) -> 124596 | E28: =SUM(E23:E27) -> 137360 | F28: =SUM(F23:F27) -> 147795

Sheet TSM Dashboard
B2: INFOSYS LTD - THREE STATEMENT MODEL DASHBOARD (2026-2029)
B3: INCOME STATEMENT
C4: 2025 | D4: 2026 | E4: 2027 | F4: 2028 | G4: 2029 | J4: Supporting Schedule
B5: Sales | C5: ='1M2026-TSM'!C6 -> 162990 | D5: ='1M2026-TSM'!D6 -> 179289 | E5: ='1M2026-TSM'!E6 -> 197217.9 | F5: ='1M2026-TSM'!F6 -> 216939.69 | G5: ='1M2026-TSM'!G6 -> 238633.66 | J5: Reserve | K5: 2025 | L5: 2026 | M5: 2027 | N5: 2028 | O5: 2029
B6: Expenses | C6: ='1M2026-TSM'!C7 -> 123754 | D6: ='1M2026-TSM'!D7 -> -125502.3 | E6: ='1M2026-TSM'!E7 -> -138052.53 | F6: ='1M2026-TSM'!F7 -> -151857.78 | G6: ='1M2026-TSM'!G7 -> -167043.56 | J6: Beginning | L6: ='1M2026-TSM'!K8 -> 93745 | M6: ='1M2026-TSM'!L8 -> 106292.36 | N6: ='1M2026-TSM'!M8 -> 120094.46 | O6: ='1M2026-TSM'!N8 -> 135276.77
B7: Operating Profit | C7: ='1M2026-TSM'!C8 -> 39236 | D7: ='1M2026-TSM'!D8 -> 53786.7 | E7: ='1M2026-TSM'!E8 -> 59165.37 | F7: ='1M2026-TSM'!F8 -> 65081.907 | G7: ='1M2026-TSM'!G8 -> 71590.098 | J7: Net Income | L7: ='1M2026-TSM'!K9 -> 34853.782 | M7: ='1M2026-TSM'!L9 -> 38339.16 | N7: ='1M2026-TSM'!M9 -> 42173.076 | O7: ='1M2026-TSM'!N9 -> 46390.383
B8: Other Income | C8: ='1M2026-TSM'!C9 -> 3600 | D8: ='1M2026-TSM'!D9 -> 0 | E8: ='1M2026-TSM'!E9 -> 0 | F8: ='1M2026-TSM'!F9 -> 0 | G8: ='1M2026-TSM'!G9 -> 0 | J8: Dividend | L8: ='1M2026-TSM'!K10 -> -22306.42 | M8: ='1M2026-TSM'!L10 -> -24537.062 | N8: ='1M2026-TSM'!M10 -> -26990.768 | O8: ='1M2026-TSM'!N10 -> -29689.845
B9: Depreciation | C9: ='1M2026-TSM'!C10 -> 4812 | D9: ='1M2026-TSM'!D10 -> -5378.67 | E9: ='1M2026-TSM'!E10 -> -5916.537 | F9: ='1M2026-TSM'!F10 -> -6508.1907 | G9: ='1M2026-TSM'!G10 -> -7159.0098 | J9: End | K9: ='1M2026-TSM'!J11 -> 93745 | L9: ='1M2026-TSM'!K11 -> 106292.36 | M9: ='1M2026-TSM'!L11 -> 120094.46 | N9: ='1M2026-TSM'!M11 -> 135276.77 | O9: ='1M2026-TSM'!N11 -> 151977.3
B10: Interest | C10: s | D10: ='1M2026-TSM'!D11 -> 0 | E10: ='1M2026-TSM'!E11 -> 0 | F10: ='1M2026-TSM'!F11 -> 0 | G10: ='1M2026-TSM'!G11 -> 0
B11: Profit before tax | C11: ='1M2026-TSM'!C12 -> 37608 | D11: ='1M2026-TSM'!D12 -> 48408.03 | E11: ='1M2026-TSM'!E12 -> 53248.833 | F11: ='1M2026-TSM'!F12 -> 58573.716 | G11: ='1M2026-TSM'!G12 -> 64431.088 | J11: Net Block | K11: 2025 | L11: 2026 | M11: 2027 | N11: 2028 | O11: 2029
B12: Tax | C12: ='1M2026-TSM'!C13 -> 10858 | D12: ='1M2026-TSM'!D13 -> -13554.248 | E12: ='1M2026-TSM'!E13 -> -14909.673 | F12: ='1M2026-TSM'!F13 -> -16400.641 | G12: ='1M2026-TSM'!G13 -> -18040.705 | J12: Beginning Net Block | L12: ='1M2026-TSM'!K17 -> 30961 | M12: ='1M2026-TSM'!L17 -> 32753.89 | N12: ='1M2026-TSM'!M17 -> 34726.069 | O12: ='1M2026-TSM'!N17 -> 36895.466
B13: Net profit | C13: ='1M2026-TSM'!C14 -> 26713 | D13: ='1M2026-TSM'!D14 -> 34853.782 | E13: ='1M2026-TSM'!E14 -> 38339.16 | F13: ='1M2026-TSM'!F14 -> 42173.076 | G13: ='1M2026-TSM'!G14 -> 46390.383 | J13: Capex | L13: ='1M2026-TSM'!K18 -> 7171.56 | M13: ='1M2026-TSM'!L18 -> 7888.716 | N13: ='1M2026-TSM'!M18 -> 8677.5876 | O13: ='1M2026-TSM'!N18 -> 9545.3464
B14: BALANCE SHEET - LIABILITIES | J14: Depreciation | L14: ='1M2026-TSM'!K19 -> -5378.67 | M14: ='1M2026-TSM'!L19 -> -5916.537 | N14: ='1M2026-TSM'!M19 -> -6508.1907 | O14: ='1M2026-TSM'!N19 -> -7159.0098
C15: 2025 | D15: 2026 | E15: 2027 | F15: 2028 | G15: 2029 | J15: End Net Block | K15: ='1M2026-TSM'!J20 -> 30961 | L15: ='1M2026-TSM'!K20 -> 32753.89 | M15: ='1M2026-TSM'!L20 -> 34726.069 | N15: ='1M2026-TSM'!M20 -> 36895.466 | O15: ='1M2026-TSM'!N20 -> 39281.802
B16: Equity Share Capital | C16: ='1M2026-TSM'!C18 -> 2073 | D16: ='1M2026-TSM'!D18 -> 2073 | E16: ='1M2026-TSM'!E18 -> 2073 | F16: ='1M2026-TSM'!F18 -> 2073 | G16: ='1M2026-TSM'!G18 -> 2073
B17: Reserves | C17: ='1M2026-TSM'!C19 -> 93745 | D17: ='1M2026-TSM'!D19 -> 106292.36 | E17: ='1M2026-TSM'!E19 -> 120094.46 | F17: ='1M2026-TSM'!F19 -> 135276.77 | G17: ='1M2026-TSM'!G19 -> 151977.3 | J17: Assumptions | K17: Value
B18: Borrowings | C18: ='1M2026-TSM'!C20 -> 8227 | D18: ='1M2026-TSM'!D20 -> 9707.86 | E18: ='1M2026-TSM'!E20 -> 11455.275 | F18: ='1M2026-TSM'!F20 -> 13517.224 | G18: ='1M2026-TSM'!G20 -> 15950.325 | J18: Sales CAGR | K18: ='1M2026-TSM'!J24 -> 0.1
B19: Other Liabilities | C19: ='1M2026-TSM'!C21 -> 43750 | D19: ='1M2026-TSM'!D21 -> 50200.92 | E19: ='1M2026-TSM'!E21 -> 55221.012 | F19: ='1M2026-TSM'!F21 -> 60743.113 | G19: ='1M2026-TSM'!G21 -> 66817.425 | J19: Expenses % sales | K19: ='1M2026-TSM'!J25 -> 0.76
B20: Total | C20: ='1M2026-TSM'!C22 -> 147795 | D20: ='1M2026-TSM'!D22 -> 168274.14 | E20: ='1M2026-TSM'!E22 -> 188843.75 | F20: ='1M2026-TSM'!F22 -> 211610.1 | G20: ='1M2026-TSM'!G22 -> 236818.05 | J20: Depreciation % sales | K20: ='1M2026-TSM'!J26 -> 0.03
B21: Balance Check | C21: ='1M2026-TSM'!C33 -> 0 | D21: ='1M2026-TSM'!D33 -> 0 | E21: ='1M2026-TSM'!E33 -> 0 | F21: ='1M2026-TSM'!F33 -> 0 | G21: ='1M2026-TSM'!G33 -> 0 | J21: Tax Rate | K21: ='1M2026-TSM'!J27 -> 0.28
B22: BALANCE SHEET - ASSETS
B23: Assets | C23: 2025 | D23: 2026 | E23: 2027 | F23: 2028 | G23: 2029 | J23: Share capital | K23: ='1M2026-TSM'!J29 -> 2073
B24: Cash | C24: ='1M2026-TSM'!C25 -> 12592 | D24: ='1M2026-TSM'!D25 -> 28665.741 | E24: ='1M2026-TSM'!E25 -> 37087.454 | F24: ='1M2026-TSM'!F25 -> 46306.82 | G24: ='1M2026-TSM'!G25 -> 56310.259 | J24: Borrowing Growth | K24: ='1M2026-TSM'!J30 -> 0.18
B25: Net Block | C25: ='1M2026-TSM'!C26 -> 30961 | D25: ='1M2026-TSM'!D26 -> 32753.89 | E25: ='1M2026-TSM'!E26 -> 34726.069 | F25: ='1M2026-TSM'!F26 -> 36895.466 | G25: ='1M2026-TSM'!G26 -> 39281.802 | J25: Others liabilities % | K25: ='1M2026-TSM'!J31 -> 0.28
B26: Capital Work in Progress | C26: ='1M2026-TSM'!C27 -> 814 | D26: ='1M2026-TSM'!D27 -> 1221 | E26: ='1M2026-TSM'!E27 -> 1831.5 | F26: ='1M2026-TSM'!F27 -> 2747.25 | G26: ='1M2026-TSM'!G27 -> 4120.875 | J26: Dividend % Net Income | K26: ='1M2026-TSM'!J32 -> 0.64
B27: Investments | C27: ='1M2026-TSM'!C28 -> 23541 | D27: ='1M2026-TSM'!D28 -> 24953.46 | E27: ='1M2026-TSM'!E28 -> 26450.668 | F27: ='1M2026-TSM'!F28 -> 28037.708 | G27: ='1M2026-TSM'!G28 -> 29719.97
B28: Other Assets | C28: ='1M2026-TSM'!C29 -> 79887 | D28: ='1M2026-TSM'!D29 -> 80680.05 | E28: ='1M2026-TSM'!E29 -> 88748.055 | F28: ='1M2026-TSM'!F29 -> 97622.861 | G28: ='1M2026-TSM'!G29 -> 107385.15 | J28: CWIP Growth | K28: ='1M2026-TSM'!J34 -> 0.05
B29: Total | C29: ='1M2026-TSM'!C30 -> 147795 | D29: ='1M2026-TSM'!D30 -> 168274.14 | E29: ='1M2026-TSM'!E30 -> 188843.75 | F29: ='1M2026-TSM'!F30 -> 211610.1 | G29: ='1M2026-TSM'!G30 -> 236818.05 | J29: Investments Growth | K29: ='1M2026-TSM'!J35 -> 0.06
B30: CASH FLOW STATEMENT | J30: Others Assets % | K30: ='1M2026-TSM'!J36 -> 0.45
B31: Cash Flow Statement | C31: 2025 | D31: 2026 | E31: 2027 | F31: 2028 | G31: 2029 | J31: Capex % Sales | K31: ='1M2026-TSM'!J37 -> 0.04
B32: Change in Operating | C32: ='1M2026-TSM'!C37 -> 0 | D32: ='1M2026-TSM'!D37 -> 34853.782 | E32: ='1M2026-TSM'!E37 -> 38339.16 | F32: ='1M2026-TSM'!F37 -> 42173.076 | G32: ='1M2026-TSM'!G37 -> 46390.383
B33: Change in Investing | C33: ='1M2026-TSM'!C38 -> 0 | D33: ='1M2026-TSM'!D38 -> 5378.67 | E33: ='1M2026-TSM'!E38 -> 5916.537 | F33: ='1M2026-TSM'!F38 -> 6508.1907 | G33: ='1M2026-TSM'!G38 -> 7159.0098
B34: Change in Financing | C34: ='1M2026-TSM'!C39 -> 0 | D34: ='1M2026-TSM'!D39 -> -793.05 | E34: ='1M2026-TSM'!E39 -> -8068.005 | F34: ='1M2026-TSM'!F39 -> -8874.8055 | G34: ='1M2026-TSM'!G39 -> -9762.2861
B35: Net Changes | C35: ='1M2026-TSM'!C40 -> 0 | D35: ='1M2026-TSM'!D40 -> 6450.92 | E35: ='1M2026-TSM'!E40 -> 5020.092 | F35: ='1M2026-TSM'!F40 -> 5522.1012 | G35: ='1M2026-TSM'!G40 -> 6074.3113
B36: Previous Cash | C36: ='1M2026-TSM'!C41 -> 0 | D36: ='1M2026-TSM'!D41 -> 45890.322 | E36: ='1M2026-TSM'!E41 -> 41207.784 | F36: ='1M2026-TSM'!F41 -> 45328.562 | G36: ='1M2026-TSM'!G41 -> 49861.418
B37: Net Cash | C37: ='1M2026-TSM'!C42 -> 0 | D37: ='1M2026-TSM'!D42 -> 0 | E37: ='1M2026-TSM'!E42 -> 0 | F37: ='1M2026-TSM'!F42 -> 0 | G37: ='1M2026-TSM'!G42 -> 0

Sheet Sheet1
